Lev crashed!
Traceback (most recent call last):
  File "/opt/hostedtoolcache/Python/3.11.5/x64/lib/python3.11/site-packages/urllib3/connectionpool.py", line 468, in _make_request
    self._validate_conn(conn)
  File "/opt/hostedtoolcache/Python/3.11.5/x64/lib/python3.11/site-packages/urllib3/connectionpool.py", line 1097, in _validate_conn
    conn.connect()
  File "/opt/hostedtoolcache/Python/3.11.5/x64/lib/python3.11/site-packages/urllib3/connection.py", line 642, in connect
    sock_and_verified = _ssl_wrap_socket_and_match_hostname(
                        ^^^^^^^^^^^^^^^^^^^^^^^^^^^^^^^^^^^^
  File "/opt/hostedtoolcache/Python/3.11.5/x64/lib/python3.11/site-packages/urllib3/connection.py", line 783, in _ssl_wrap_socket_and_match_hostname
    ssl_sock = ssl_wrap_socket(
               ^^^^^^^^^^^^^^^^
  File "/opt/hostedtoolcache/Python/3.11.5/x64/lib/python3.11/site-packages/urllib3/util/ssl_.py", line 471, in ssl_wrap_socket
    ssl_sock = _ssl_wrap_socket_impl(sock, context, tls_in_tls, server_hostname)
               ^^^^^^^^^^^^^^^^^^^^^^^^^^^^^^^^^^^^^^^^^^^^^^^^^^^^^^^^^^^^^^^^^
  File "/opt/hostedtoolcache/Python/3.11.5/x64/lib/python3.11/site-packages/urllib3/util/ssl_.py", line 515, in _ssl_wrap_socket_impl
    return ssl_context.wrap_socket(sock, server_hostname=server_hostname)
           ^^^^^^^^^^^^^^^^^^^^^^^^^^^^^^^^^^^^^^^^^^^^^^^^^^^^^^^^^^^^^^
  File "/opt/hostedtoolcache/Python/3.11.5/x64/lib/python3.11/ssl.py", line 517, in wrap_socket
    return self.sslsocket_class._create(
           ^^^^^^^^^^^^^^^^^^^^^^^^^^^^^
  File "/opt/hostedtoolcache/Python/3.11.5/x64/lib/python3.11/ssl.py", line 1108, in _create
    self.do_handshake()
  File "/opt/hostedtoolcache/Python/3.11.5/x64/lib/python3.11/ssl.py", line 1379, in do_handshake
    self._sslobj.do_handshake()
ssl.SSLCertVerificationError: [SSL: CERTIFICATE_VERIFY_FAILED] certificate verify failed: unable to get local issuer certificate (_ssl.c:1006)

During handling of the above exception, another exception occurred:

Traceback (most recent call last):
  File "/opt/hostedtoolcache/Python/3.11.5/x64/lib/python3.11/site-packages/urllib3/connectionpool.py", line 791, in urlopen
    response = self._make_request(
               ^^^^^^^^^^^^^^^^^^^
  File "/opt/hostedtoolcache/Python/3.11.5/x64/lib/python3.11/site-packages/urllib3/connectionpool.py", line 492, in _make_request
    raise new_e
urllib3.exceptions.SSLError: [SSL: CERTIFICATE_VERIFY_FAILED] certificate verify failed: unable to get local issuer certificate (_ssl.c:1006)

The above exception was the direct cause of the following exception:

Traceback (most recent call last):
  File "/opt/hostedtoolcache/Python/3.11.5/x64/lib/python3.11/site-packages/requests/adapters.py", line 486, in send
    resp = conn.urlopen(
           ^^^^^^^^^^^^^
  File "/opt/hostedtoolcache/Python/3.11.5/x64/lib/python3.11/site-packages/urllib3/connectionpool.py", line 845, in urlopen
    retries = retries.increment(
              ^^^^^^^^^^^^^^^^^^
  File "/opt/hostedtoolcache/Python/3.11.5/x64/lib/python3.11/site-packages/urllib3/util/retry.py", line 515, in increment
    raise MaxRetryError(_pool, url, reason) from reason  # type: ignore[arg-type]
    ^^^^^^^^^^^^^^^^^^^^^^^^^^^^^^^^^^^^^^^^^^^^^^^^^^^
urllib3.exceptions.MaxRetryError: HTTPSConnectionPool(host='ticket.lev.co.il', port=443): Max retries exceeded with url: /api/presentations?locationId=1150&includeSynopsis=0 (Caused by SSLError(SSLCertVerificationError(1, '[SSL: CERTIFICATE_VERIFY_FAILED] certificate verify failed: unable to get local issuer certificate (_ssl.c:1006)')))

During handling of the above exception, another exception occurred:

Traceback (most recent call last):
  File "/home/runner/work/Movie-Time-Server/Movie-Time-Server/main.py", line 64, in get_all_screenings
    lev.get_screenings(year, month, day, s)
  File "/home/runner/work/Movie-Time-Server/Movie-Time-Server/lev.py", line 111, in get_screenings
    get_by_location(location, date, format_date, s)
  File "/home/runner/work/Movie-Time-Server/Movie-Time-Server/lev.py", line 88, in get_by_location
    res = s.get(url)
          ^^^^^^^^^^
  File "/opt/hostedtoolcache/Python/3.11.5/x64/lib/python3.11/site-packages/requests/sessions.py", line 602, in get
    return self.request("GET", url, **kwargs)
           ^^^^^^^^^^^^^^^^^^^^^^^^^^^^^^^^^^
  File "/opt/hostedtoolcache/Python/3.11.5/x64/lib/python3.11/site-packages/requests/sessions.py", line 589, in request
    resp = self.send(prep, **send_kwargs)
           ^^^^^^^^^^^^^^^^^^^^^^^^^^^^^^
  File "/opt/hostedtoolcache/Python/3.11.5/x64/lib/python3.11/site-packages/requests/sessions.py", line 703, in send
    r = adapter.send(request, **kwargs)
        ^^^^^^^^^^^^^^^^^^^^^^^^^^^^^^^
  File "/opt/hostedtoolcache/Python/3.11.5/x64/lib/python3.11/site-packages/requests/adapters.py", line 517, in send
    raise SSLError(e, request=request)
requests.exceptions.SSLError: HTTPSConnectionPool(host='ticket.lev.co.il', port=443): Max retries exceeded with url: /api/presentations?locationId=1150&includeSynopsis=0 (Caused by SSLError(SSLCertVerificationError(1, '[SSL: CERTIFICATE_VERIFY_FAILED] certificate verify failed: unable to get local issuer certificate (_ssl.c:1006)')))
Lev crashed!
Traceback (most recent call last):
  File "/opt/hostedtoolcache/Python/3.11.5/x64/lib/python3.11/site-packages/urllib3/connectionpool.py", line 468, in _make_request
    self._validate_conn(conn)
  File "/opt/hostedtoolcache/Python/3.11.5/x64/lib/python3.11/site-packages/urllib3/connectionpool.py", line 1097, in _validate_conn
    conn.connect()
  File "/opt/hostedtoolcache/Python/3.11.5/x64/lib/python3.11/site-packages/urllib3/connection.py", line 642, in connect
    sock_and_verified = _ssl_wrap_socket_and_match_hostname(
                        ^^^^^^^^^^^^^^^^^^^^^^^^^^^^^^^^^^^^
  File "/opt/hostedtoolcache/Python/3.11.5/x64/lib/python3.11/site-packages/urllib3/connection.py", line 783, in _ssl_wrap_socket_and_match_hostname
    ssl_sock = ssl_wrap_socket(
               ^^^^^^^^^^^^^^^^
  File "/opt/hostedtoolcache/Python/3.11.5/x64/lib/python3.11/site-packages/urllib3/util/ssl_.py", line 471, in ssl_wrap_socket
    ssl_sock = _ssl_wrap_socket_impl(sock, context, tls_in_tls, server_hostname)
               ^^^^^^^^^^^^^^^^^^^^^^^^^^^^^^^^^^^^^^^^^^^^^^^^^^^^^^^^^^^^^^^^^
  File "/opt/hostedtoolcache/Python/3.11.5/x64/lib/python3.11/site-packages/urllib3/util/ssl_.py", line 515, in _ssl_wrap_socket_impl
    return ssl_context.wrap_socket(sock, server_hostname=server_hostname)
           ^^^^^^^^^^^^^^^^^^^^^^^^^^^^^^^^^^^^^^^^^^^^^^^^^^^^^^^^^^^^^^
  File "/opt/hostedtoolcache/Python/3.11.5/x64/lib/python3.11/ssl.py", line 517, in wrap_socket
    return self.sslsocket_class._create(
           ^^^^^^^^^^^^^^^^^^^^^^^^^^^^^
  File "/opt/hostedtoolcache/Python/3.11.5/x64/lib/python3.11/ssl.py", line 1108, in _create
    self.do_handshake()
  File "/opt/hostedtoolcache/Python/3.11.5/x64/lib/python3.11/ssl.py", line 1379, in do_handshake
    self._sslobj.do_handshake()
ssl.SSLCertVerificationError: [SSL: CERTIFICATE_VERIFY_FAILED] certificate verify failed: unable to get local issuer certificate (_ssl.c:1006)

During handling of the above exception, another exception occurred:

Traceback (most recent call last):
  File "/opt/hostedtoolcache/Python/3.11.5/x64/lib/python3.11/site-packages/urllib3/connectionpool.py", line 791, in urlopen
    response = self._make_request(
               ^^^^^^^^^^^^^^^^^^^
  File "/opt/hostedtoolcache/Python/3.11.5/x64/lib/python3.11/site-packages/urllib3/connectionpool.py", line 492, in _make_request
    raise new_e
urllib3.exceptions.SSLError: [SSL: CERTIFICATE_VERIFY_FAILED] certificate verify failed: unable to get local issuer certificate (_ssl.c:1006)

The above exception was the direct cause of the following exception:

Traceback (most recent call last):
  File "/opt/hostedtoolcache/Python/3.11.5/x64/lib/python3.11/site-packages/requests/adapters.py", line 486, in send
    resp = conn.urlopen(
           ^^^^^^^^^^^^^
  File "/opt/hostedtoolcache/Python/3.11.5/x64/lib/python3.11/site-packages/urllib3/connectionpool.py", line 845, in urlopen
    retries = retries.increment(
              ^^^^^^^^^^^^^^^^^^
  File "/opt/hostedtoolcache/Python/3.11.5/x64/lib/python3.11/site-packages/urllib3/util/retry.py", line 515, in increment
    raise MaxRetryError(_pool, url, reason) from reason  # type: ignore[arg-type]
    ^^^^^^^^^^^^^^^^^^^^^^^^^^^^^^^^^^^^^^^^^^^^^^^^^^^
urllib3.exceptions.MaxRetryError: HTTPSConnectionPool(host='ticket.lev.co.il', port=443): Max retries exceeded with url: /api/presentations?locationId=1150&includeSynopsis=0 (Caused by SSLError(SSLCertVerificationError(1, '[SSL: CERTIFICATE_VERIFY_FAILED] certificate verify failed: unable to get local issuer certificate (_ssl.c:1006)')))

During handling of the above exception, another exception occurred:

Traceback (most recent call last):
  File "/home/runner/work/Movie-Time-Server/Movie-Time-Server/main.py", line 64, in get_all_screenings
    lev.get_screenings(year, month, day, s)
  File "/home/runner/work/Movie-Time-Server/Movie-Time-Server/lev.py", line 111, in get_screenings
    get_by_location(location, date, format_date, s)
  File "/home/runner/work/Movie-Time-Server/Movie-Time-Server/lev.py", line 88, in get_by_location
    res = s.get(url)
          ^^^^^^^^^^
  File "/opt/hostedtoolcache/Python/3.11.5/x64/lib/python3.11/site-packages/requests/sessions.py", line 602, in get
    return self.request("GET", url, **kwargs)
           ^^^^^^^^^^^^^^^^^^^^^^^^^^^^^^^^^^
  File "/opt/hostedtoolcache/Python/3.11.5/x64/lib/python3.11/site-packages/requests/sessions.py", line 589, in request
    resp = self.send(prep, **send_kwargs)
           ^^^^^^^^^^^^^^^^^^^^^^^^^^^^^^
  File "/opt/hostedtoolcache/Python/3.11.5/x64/lib/python3.11/site-packages/requests/sessions.py", line 703, in send
    r = adapter.send(request, **kwargs)
        ^^^^^^^^^^^^^^^^^^^^^^^^^^^^^^^
  File "/opt/hostedtoolcache/Python/3.11.5/x64/lib/python3.11/site-packages/requests/adapters.py", line 517, in send
    raise SSLError(e, request=request)
requests.exceptions.SSLError: HTTPSConnectionPool(host='ticket.lev.co.il', port=443): Max retries exceeded with url: /api/presentations?locationId=1150&includeSynopsis=0 (Caused by SSLError(SSLCertVerificationError(1, '[SSL: CERTIFICATE_VERIFY_FAILED] certificate verify failed: unable to get local issuer certificate (_ssl.c:1006)')))
Lev crashed!
Traceback (most recent call last):
  File "/opt/hostedtoolcache/Python/3.11.5/x64/lib/python3.11/site-packages/urllib3/connectionpool.py", line 468, in _make_request
    self._validate_conn(conn)
  File "/opt/hostedtoolcache/Python/3.11.5/x64/lib/python3.11/site-packages/urllib3/connectionpool.py", line 1097, in _validate_conn
    conn.connect()
  File "/opt/hostedtoolcache/Python/3.11.5/x64/lib/python3.11/site-packages/urllib3/connection.py", line 642, in connect
    sock_and_verified = _ssl_wrap_socket_and_match_hostname(
                        ^^^^^^^^^^^^^^^^^^^^^^^^^^^^^^^^^^^^
  File "/opt/hostedtoolcache/Python/3.11.5/x64/lib/python3.11/site-packages/urllib3/connection.py", line 783, in _ssl_wrap_socket_and_match_hostname
    ssl_sock = ssl_wrap_socket(
               ^^^^^^^^^^^^^^^^
  File "/opt/hostedtoolcache/Python/3.11.5/x64/lib/python3.11/site-packages/urllib3/util/ssl_.py", line 471, in ssl_wrap_socket
    ssl_sock = _ssl_wrap_socket_impl(sock, context, tls_in_tls, server_hostname)
               ^^^^^^^^^^^^^^^^^^^^^^^^^^^^^^^^^^^^^^^^^^^^^^^^^^^^^^^^^^^^^^^^^
  File "/opt/hostedtoolcache/Python/3.11.5/x64/lib/python3.11/site-packages/urllib3/util/ssl_.py", line 515, in _ssl_wrap_socket_impl
    return ssl_context.wrap_socket(sock, server_hostname=server_hostname)
           ^^^^^^^^^^^^^^^^^^^^^^^^^^^^^^^^^^^^^^^^^^^^^^^^^^^^^^^^^^^^^^
  File "/opt/hostedtoolcache/Python/3.11.5/x64/lib/python3.11/ssl.py", line 517, in wrap_socket
    return self.sslsocket_class._create(
           ^^^^^^^^^^^^^^^^^^^^^^^^^^^^^
  File "/opt/hostedtoolcache/Python/3.11.5/x64/lib/python3.11/ssl.py", line 1108, in _create
    self.do_handshake()
  File "/opt/hostedtoolcache/Python/3.11.5/x64/lib/python3.11/ssl.py", line 1379, in do_handshake
    self._sslobj.do_handshake()
ssl.SSLCertVerificationError: [SSL: CERTIFICATE_VERIFY_FAILED] certificate verify failed: unable to get local issuer certificate (_ssl.c:1006)

During handling of the above exception, another exception occurred:

Traceback (most recent call last):
  File "/opt/hostedtoolcache/Python/3.11.5/x64/lib/python3.11/site-packages/urllib3/connectionpool.py", line 791, in urlopen
    response = self._make_request(
               ^^^^^^^^^^^^^^^^^^^
  File "/opt/hostedtoolcache/Python/3.11.5/x64/lib/python3.11/site-packages/urllib3/connectionpool.py", line 492, in _make_request
    raise new_e
urllib3.exceptions.SSLError: [SSL: CERTIFICATE_VERIFY_FAILED] certificate verify failed: unable to get local issuer certificate (_ssl.c:1006)

The above exception was the direct cause of the following exception:

Traceback (most recent call last):
  File "/opt/hostedtoolcache/Python/3.11.5/x64/lib/python3.11/site-packages/requests/adapters.py", line 486, in send
    resp = conn.urlopen(
           ^^^^^^^^^^^^^
  File "/opt/hostedtoolcache/Python/3.11.5/x64/lib/python3.11/site-packages/urllib3/connectionpool.py", line 845, in urlopen
    retries = retries.increment(
              ^^^^^^^^^^^^^^^^^^
  File "/opt/hostedtoolcache/Python/3.11.5/x64/lib/python3.11/site-packages/urllib3/util/retry.py", line 515, in increment
    raise MaxRetryError(_pool, url, reason) from reason  # type: ignore[arg-type]
    ^^^^^^^^^^^^^^^^^^^^^^^^^^^^^^^^^^^^^^^^^^^^^^^^^^^
urllib3.exceptions.MaxRetryError: HTTPSConnectionPool(host='ticket.lev.co.il', port=443): Max retries exceeded with url: /api/presentations?locationId=1150&includeSynopsis=0 (Caused by SSLError(SSLCertVerificationError(1, '[SSL: CERTIFICATE_VERIFY_FAILED] certificate verify failed: unable to get local issuer certificate (_ssl.c:1006)')))

During handling of the above exception, another exception occurred:

Traceback (most recent call last):
  File "/home/runner/work/Movie-Time-Server/Movie-Time-Server/main.py", line 64, in get_all_screenings
    lev.get_screenings(year, month, day, s)
  File "/home/runner/work/Movie-Time-Server/Movie-Time-Server/lev.py", line 111, in get_screenings
    get_by_location(location, date, format_date, s)
  File "/home/runner/work/Movie-Time-Server/Movie-Time-Server/lev.py", line 88, in get_by_location
    res = s.get(url)
          ^^^^^^^^^^
  File "/opt/hostedtoolcache/Python/3.11.5/x64/lib/python3.11/site-packages/requests/sessions.py", line 602, in get
    return self.request("GET", url, **kwargs)
           ^^^^^^^^^^^^^^^^^^^^^^^^^^^^^^^^^^
  File "/opt/hostedtoolcache/Python/3.11.5/x64/lib/python3.11/site-packages/requests/sessions.py", line 589, in request
    resp = self.send(prep, **send_kwargs)
           ^^^^^^^^^^^^^^^^^^^^^^^^^^^^^^
  File "/opt/hostedtoolcache/Python/3.11.5/x64/lib/python3.11/site-packages/requests/sessions.py", line 703, in send
    r = adapter.send(request, **kwargs)
        ^^^^^^^^^^^^^^^^^^^^^^^^^^^^^^^
  File "/opt/hostedtoolcache/Python/3.11.5/x64/lib/python3.11/site-packages/requests/adapters.py", line 517, in send
    raise SSLError(e, request=request)
requests.exceptions.SSLError: HTTPSConnectionPool(host='ticket.lev.co.il', port=443): Max retries exceeded with url: /api/presentations?locationId=1150&includeSynopsis=0 (Caused by SSLError(SSLCertVerificationError(1, '[SSL: CERTIFICATE_VERIFY_FAILED] certificate verify failed: unable to get local issuer certificate (_ssl.c:1006)')))
Lev crashed!
Traceback (most recent call last):
  File "/opt/hostedtoolcache/Python/3.11.5/x64/lib/python3.11/site-packages/urllib3/connectionpool.py", line 468, in _make_request
    self._validate_conn(conn)
  File "/opt/hostedtoolcache/Python/3.11.5/x64/lib/python3.11/site-packages/urllib3/connectionpool.py", line 1097, in _validate_conn
    conn.connect()
  File "/opt/hostedtoolcache/Python/3.11.5/x64/lib/python3.11/site-packages/urllib3/connection.py", line 642, in connect
    sock_and_verified = _ssl_wrap_socket_and_match_hostname(
                        ^^^^^^^^^^^^^^^^^^^^^^^^^^^^^^^^^^^^
  File "/opt/hostedtoolcache/Python/3.11.5/x64/lib/python3.11/site-packages/urllib3/connection.py", line 783, in _ssl_wrap_socket_and_match_hostname
    ssl_sock = ssl_wrap_socket(
               ^^^^^^^^^^^^^^^^
  File "/opt/hostedtoolcache/Python/3.11.5/x64/lib/python3.11/site-packages/urllib3/util/ssl_.py", line 471, in ssl_wrap_socket
    ssl_sock = _ssl_wrap_socket_impl(sock, context, tls_in_tls, server_hostname)
               ^^^^^^^^^^^^^^^^^^^^^^^^^^^^^^^^^^^^^^^^^^^^^^^^^^^^^^^^^^^^^^^^^
  File "/opt/hostedtoolcache/Python/3.11.5/x64/lib/python3.11/site-packages/urllib3/util/ssl_.py", line 515, in _ssl_wrap_socket_impl
    return ssl_context.wrap_socket(sock, server_hostname=server_hostname)
           ^^^^^^^^^^^^^^^^^^^^^^^^^^^^^^^^^^^^^^^^^^^^^^^^^^^^^^^^^^^^^^
  File "/opt/hostedtoolcache/Python/3.11.5/x64/lib/python3.11/ssl.py", line 517, in wrap_socket
    return self.sslsocket_class._create(
           ^^^^^^^^^^^^^^^^^^^^^^^^^^^^^
  File "/opt/hostedtoolcache/Python/3.11.5/x64/lib/python3.11/ssl.py", line 1108, in _create
    self.do_handshake()
  File "/opt/hostedtoolcache/Python/3.11.5/x64/lib/python3.11/ssl.py", line 1379, in do_handshake
    self._sslobj.do_handshake()
ssl.SSLCertVerificationError: [SSL: CERTIFICATE_VERIFY_FAILED] certificate verify failed: unable to get local issuer certificate (_ssl.c:1006)

During handling of the above exception, another exception occurred:

Traceback (most recent call last):
  File "/opt/hostedtoolcache/Python/3.11.5/x64/lib/python3.11/site-packages/urllib3/connectionpool.py", line 791, in urlopen
    response = self._make_request(
               ^^^^^^^^^^^^^^^^^^^
  File "/opt/hostedtoolcache/Python/3.11.5/x64/lib/python3.11/site-packages/urllib3/connectionpool.py", line 492, in _make_request
    raise new_e
urllib3.exceptions.SSLError: [SSL: CERTIFICATE_VERIFY_FAILED] certificate verify failed: unable to get local issuer certificate (_ssl.c:1006)

The above exception was the direct cause of the following exception:

Traceback (most recent call last):
  File "/opt/hostedtoolcache/Python/3.11.5/x64/lib/python3.11/site-packages/requests/adapters.py", line 486, in send
    resp = conn.urlopen(
           ^^^^^^^^^^^^^
  File "/opt/hostedtoolcache/Python/3.11.5/x64/lib/python3.11/site-packages/urllib3/connectionpool.py", line 845, in urlopen
    retries = retries.increment(
              ^^^^^^^^^^^^^^^^^^
  File "/opt/hostedtoolcache/Python/3.11.5/x64/lib/python3.11/site-packages/urllib3/util/retry.py", line 515, in increment
    raise MaxRetryError(_pool, url, reason) from reason  # type: ignore[arg-type]
    ^^^^^^^^^^^^^^^^^^^^^^^^^^^^^^^^^^^^^^^^^^^^^^^^^^^
urllib3.exceptions.MaxRetryError: HTTPSConnectionPool(host='ticket.lev.co.il', port=443): Max retries exceeded with url: /api/presentations?locationId=1150&includeSynopsis=0 (Caused by SSLError(SSLCertVerificationError(1, '[SSL: CERTIFICATE_VERIFY_FAILED] certificate verify failed: unable to get local issuer certificate (_ssl.c:1006)')))

During handling of the above exception, another exception occurred:

Traceback (most recent call last):
  File "/home/runner/work/Movie-Time-Server/Movie-Time-Server/main.py", line 64, in get_all_screenings
    lev.get_screenings(year, month, day, s)
  File "/home/runner/work/Movie-Time-Server/Movie-Time-Server/lev.py", line 111, in get_screenings
    get_by_location(location, date, format_date, s)
  File "/home/runner/work/Movie-Time-Server/Movie-Time-Server/lev.py", line 88, in get_by_location
    res = s.get(url)
          ^^^^^^^^^^
  File "/opt/hostedtoolcache/Python/3.11.5/x64/lib/python3.11/site-packages/requests/sessions.py", line 602, in get
    return self.request("GET", url, **kwargs)
           ^^^^^^^^^^^^^^^^^^^^^^^^^^^^^^^^^^
  File "/opt/hostedtoolcache/Python/3.11.5/x64/lib/python3.11/site-packages/requests/sessions.py", line 589, in request
    resp = self.send(prep, **send_kwargs)
           ^^^^^^^^^^^^^^^^^^^^^^^^^^^^^^
  File "/opt/hostedtoolcache/Python/3.11.5/x64/lib/python3.11/site-packages/requests/sessions.py", line 703, in send
    r = adapter.send(request, **kwargs)
        ^^^^^^^^^^^^^^^^^^^^^^^^^^^^^^^
  File "/opt/hostedtoolcache/Python/3.11.5/x64/lib/python3.11/site-packages/requests/adapters.py", line 517, in send
    raise SSLError(e, request=request)
requests.exceptions.SSLError: HTTPSConnectionPool(host='ticket.lev.co.il', port=443): Max retries exceeded with url: /api/presentations?locationId=1150&includeSynopsis=0 (Caused by SSLError(SSLCertVerificationError(1, '[SSL: CERTIFICATE_VERIFY_FAILED] certificate verify failed: unable to get local issuer certificate (_ssl.c:1006)')))
Lev crashed!
Traceback (most recent call last):
  File "/opt/hostedtoolcache/Python/3.11.5/x64/lib/python3.11/site-packages/urllib3/connectionpool.py", line 468, in _make_request
    self._validate_conn(conn)
  File "/opt/hostedtoolcache/Python/3.11.5/x64/lib/python3.11/site-packages/urllib3/connectionpool.py", line 1097, in _validate_conn
    conn.connect()
  File "/opt/hostedtoolcache/Python/3.11.5/x64/lib/python3.11/site-packages/urllib3/connection.py", line 642, in connect
    sock_and_verified = _ssl_wrap_socket_and_match_hostname(
                        ^^^^^^^^^^^^^^^^^^^^^^^^^^^^^^^^^^^^
  File "/opt/hostedtoolcache/Python/3.11.5/x64/lib/python3.11/site-packages/urllib3/connection.py", line 783, in _ssl_wrap_socket_and_match_hostname
    ssl_sock = ssl_wrap_socket(
               ^^^^^^^^^^^^^^^^
  File "/opt/hostedtoolcache/Python/3.11.5/x64/lib/python3.11/site-packages/urllib3/util/ssl_.py", line 471, in ssl_wrap_socket
    ssl_sock = _ssl_wrap_socket_impl(sock, context, tls_in_tls, server_hostname)
               ^^^^^^^^^^^^^^^^^^^^^^^^^^^^^^^^^^^^^^^^^^^^^^^^^^^^^^^^^^^^^^^^^
  File "/opt/hostedtoolcache/Python/3.11.5/x64/lib/python3.11/site-packages/urllib3/util/ssl_.py", line 515, in _ssl_wrap_socket_impl
    return ssl_context.wrap_socket(sock, server_hostname=server_hostname)
           ^^^^^^^^^^^^^^^^^^^^^^^^^^^^^^^^^^^^^^^^^^^^^^^^^^^^^^^^^^^^^^
  File "/opt/hostedtoolcache/Python/3.11.5/x64/lib/python3.11/ssl.py", line 517, in wrap_socket
    return self.sslsocket_class._create(
           ^^^^^^^^^^^^^^^^^^^^^^^^^^^^^
  File "/opt/hostedtoolcache/Python/3.11.5/x64/lib/python3.11/ssl.py", line 1108, in _create
    self.do_handshake()
  File "/opt/hostedtoolcache/Python/3.11.5/x64/lib/python3.11/ssl.py", line 1379, in do_handshake
    self._sslobj.do_handshake()
ssl.SSLCertVerificationError: [SSL: CERTIFICATE_VERIFY_FAILED] certificate verify failed: unable to get local issuer certificate (_ssl.c:1006)

During handling of the above exception, another exception occurred:

Traceback (most recent call last):
  File "/opt/hostedtoolcache/Python/3.11.5/x64/lib/python3.11/site-packages/urllib3/connectionpool.py", line 791, in urlopen
    response = self._make_request(
               ^^^^^^^^^^^^^^^^^^^
  File "/opt/hostedtoolcache/Python/3.11.5/x64/lib/python3.11/site-packages/urllib3/connectionpool.py", line 492, in _make_request
    raise new_e
urllib3.exceptions.SSLError: [SSL: CERTIFICATE_VERIFY_FAILED] certificate verify failed: unable to get local issuer certificate (_ssl.c:1006)

The above exception was the direct cause of the following exception:

Traceback (most recent call last):
  File "/opt/hostedtoolcache/Python/3.11.5/x64/lib/python3.11/site-packages/requests/adapters.py", line 486, in send
    resp = conn.urlopen(
           ^^^^^^^^^^^^^
  File "/opt/hostedtoolcache/Python/3.11.5/x64/lib/python3.11/site-packages/urllib3/connectionpool.py", line 845, in urlopen
    retries = retries.increment(
              ^^^^^^^^^^^^^^^^^^
  File "/opt/hostedtoolcache/Python/3.11.5/x64/lib/python3.11/site-packages/urllib3/util/retry.py", line 515, in increment
    raise MaxRetryError(_pool, url, reason) from reason  # type: ignore[arg-type]
    ^^^^^^^^^^^^^^^^^^^^^^^^^^^^^^^^^^^^^^^^^^^^^^^^^^^
urllib3.exceptions.MaxRetryError: HTTPSConnectionPool(host='ticket.lev.co.il', port=443): Max retries exceeded with url: /api/presentations?locationId=1150&includeSynopsis=0 (Caused by SSLError(SSLCertVerificationError(1, '[SSL: CERTIFICATE_VERIFY_FAILED] certificate verify failed: unable to get local issuer certificate (_ssl.c:1006)')))

During handling of the above exception, another exception occurred:

Traceback (most recent call last):
  File "/home/runner/work/Movie-Time-Server/Movie-Time-Server/main.py", line 64, in get_all_screenings
    lev.get_screenings(year, month, day, s)
  File "/home/runner/work/Movie-Time-Server/Movie-Time-Server/lev.py", line 111, in get_screenings
    get_by_location(location, date, format_date, s)
  File "/home/runner/work/Movie-Time-Server/Movie-Time-Server/lev.py", line 88, in get_by_location
    res = s.get(url)
          ^^^^^^^^^^
  File "/opt/hostedtoolcache/Python/3.11.5/x64/lib/python3.11/site-packages/requests/sessions.py", line 602, in get
    return self.request("GET", url, **kwargs)
           ^^^^^^^^^^^^^^^^^^^^^^^^^^^^^^^^^^
  File "/opt/hostedtoolcache/Python/3.11.5/x64/lib/python3.11/site-packages/requests/sessions.py", line 589, in request
    resp = self.send(prep, **send_kwargs)
           ^^^^^^^^^^^^^^^^^^^^^^^^^^^^^^
  File "/opt/hostedtoolcache/Python/3.11.5/x64/lib/python3.11/site-packages/requests/sessions.py", line 703, in send
    r = adapter.send(request, **kwargs)
        ^^^^^^^^^^^^^^^^^^^^^^^^^^^^^^^
  File "/opt/hostedtoolcache/Python/3.11.5/x64/lib/python3.11/site-packages/requests/adapters.py", line 517, in send
    raise SSLError(e, request=request)
requests.exceptions.SSLError: HTTPSConnectionPool(host='ticket.lev.co.il', port=443): Max retries exceeded with url: /api/presentations?locationId=1150&includeSynopsis=0 (Caused by SSLError(SSLCertVerificationError(1, '[SSL: CERTIFICATE_VERIFY_FAILED] certificate verify failed: unable to get local issuer certificate (_ssl.c:1006)')))
