Cinema city crashed!
Traceback (most recent call last):
  File "/opt/hostedtoolcache/Python/3.11.5/x64/lib/python3.11/site-packages/requests/models.py", line 971, in json
    return complexjson.loads(self.text, **kwargs)
           ^^^^^^^^^^^^^^^^^^^^^^^^^^^^^^^^^^^^^^
  File "/opt/hostedtoolcache/Python/3.11.5/x64/lib/python3.11/json/__init__.py", line 346, in loads
    return _default_decoder.decode(s)
           ^^^^^^^^^^^^^^^^^^^^^^^^^^
  File "/opt/hostedtoolcache/Python/3.11.5/x64/lib/python3.11/json/decoder.py", line 337, in decode
    obj, end = self.raw_decode(s, idx=_w(s, 0).end())
               ^^^^^^^^^^^^^^^^^^^^^^^^^^^^^^^^^^^^^^
  File "/opt/hostedtoolcache/Python/3.11.5/x64/lib/python3.11/json/decoder.py", line 355, in raw_decode
    raise JSONDecodeError("Expecting value", s, err.value) from None
json.decoder.JSONDecodeError: Expecting value: line 1 column 1 (char 0)

During handling of the above exception, another exception occurred:

Traceback (most recent call last):
  File "/home/runner/work/Movie-Time-Server/Movie-Time-Server/main.py", line 59, in get_all_screenings
    cinema_city.get_screenings(year, month, day, s)
  File "/home/runner/work/Movie-Time-Server/Movie-Time-Server/cinema_city.py", line 113, in get_screenings
    get_by_location(location, date, s)
  File "/home/runner/work/Movie-Time-Server/Movie-Time-Server/cinema_city.py", line 88, in get_by_location
    new_date = get_date(location, date, s)
               ^^^^^^^^^^^^^^^^^^^^^^^^^^^
  File "/home/runner/work/Movie-Time-Server/Movie-Time-Server/cinema_city.py", line 78, in get_date
    data = res.json()
           ^^^^^^^^^^
  File "/opt/hostedtoolcache/Python/3.11.5/x64/lib/python3.11/site-packages/requests/models.py", line 975, in json
    raise RequestsJSONDecodeError(e.msg, e.doc, e.pos)
requests.exceptions.JSONDecodeError: Expecting value: line 1 column 1 (char 0)
